Workbook

Sheet Hypothèses
A1: BRIDGES : hypothèses de l'estimation de charge
A3: Cellules bleues = paramètres modifiables. L'onglet 'Estimation' se recalcule automatiquement.
A5: Paramètre | B5: Valeur | C5: Unité | D5: Source / justification
A6: CADENCES ET TEMPS UNITAIRES
A7: Débit de screening | B7: 350 | C7: abstracts/sem | D7: Débit réel soutenable mesuré (fatigue incluse)
A8: Temps téléchargement OA (manuel) | B8: 3 | C8: min/article | D8: Manuel : recherche + téléchargement + renommage
A9: Temps full-text (lecture+décision) | B9: 15 | C9: min/article | D9: Tri full-text : décision inclure/exclure sur critères
A10: Temps validation fiche IA | B10: 20 | C10: min/article | D10: Validation fiche : ~13% des champs à confiance moy./basse (mesuré sur 207 fiches)
A11: TEMPS DE TRAVAIL
A12: Heures travaillées / semaine | B12: 37 | C12: h/semaine | D12: Temps plein
A13: Jours travaillés / semaine | B13: 5 | C13: j/semaine | D13: Temps plein
A14: Nb de personnes | B14: 1 | C14: personnes | D14: STRUCTURANT : tous les calculs supposent 1 personne. Modifier ici pour simuler une équipe.
A15: Semaines restantes au contrat | B15: 3 | C15: semaines | D15: Contrat jusqu'à fin juillet 2026
A16: VOLUMES DU CORPUS
A17: Taux d'inclusion (abstract→full-text) | B17: 0.5 | C17: proportion | D17: Part des abstracts jugés pertinents (prudent)
A18: Abstracts WoS restants | B18: 2011 | C18: abstracts | D18: Non-vus (ASReview)
A19: Inclus déjà identifiés | B19: 816 | C19: articles | D19: Déjà jugés pertinents
A20: PDF déjà téléchargés | B20: 207 | C20: articles | D20: OA récupérés
A21: OA restants à télécharger | B21: 329 | C21: articles | D21: 536 OA - 207 déjà faits
A22: Paywall à demander (biblio) | B22: 277 | C22: articles | D22: Sous abonnement éditeur
A23: Extraction Python déjà faite | B23: 207 | C23: articles | D23: Fiches pré-remplies produites
A24: SNOWBALLING (mesuré citationchaser / Lens.org, 816 art.)
A25: Snowballing forward (mesuré) | B25: 9642 | C25: articles | D25: Citants uniques
A26: Snowballing backward (mesuré) | B26: 46644 | C26: références | D26: Références uniques
A27: Snowballing part conservée | B27: 0.4 | C27: proportion | D27: Très approximatif (voir note onglet Estimation)
A28: FORFAITS (phases 03-05)
A29: Forfait préparation demande biblio | B29: 0.5 | C29: jours | D29: Préparation liste DOI + suivi (hors délai biblio)
A30: Forfait extraction Python (/207) | B30: 0.5 | C30: jours | D30: Mesuré : ~½ journée pour 207 articles
A31: Forfait harmonisation + consolidation | B31: 0.5 | C31: semaines | D31: Relance code + vérification experte de chaque modèle (cas ambigus, nouvelles familles)
A32: Forfait analyses/visualisations restantes | B32: 1 | C32: semaines | D32: Radars/heatmap/clusters faits ; reste à finaliser
A33: Forfait rédaction (manuscrit) | B33: 6 | C33: semaines | D33: Manuscrit + suppléments + révisions
A34: Forfait guide de choix de modèle | B34: 1 | C34: semaines | D34: Livrable BRIDGES
A36: SECONDE VAGUE (issus du screening des 2011)
A37: Taux d'inclusion des 2011 restants | B37: 0.5 | C37: proportion | D37: Prudent ; baisse attendue (active learning a écrémé)
A39: LITTÉRATURE GRISE (Publish or Perish, FAO, thèses)
A40: Documents littérature grise (estimés) | B40: 50 | C40: documents | D40: Estimation grossière (test PoP bref) ; à affiner
A41: Temps tri document long | B41: 25 | C41: min/document | D41: Rapports FAO / thèses : longs (résumé, TOC, intro, conclu)
A42: Taux d'inclusion littérature grise | B42: 0.3 | C42: proportion | D42: Part jugée pertinente puis à extraire
A43: Temps validation fiche litt. grise | B43: 45 | C43: min/document | D43: Documents longs (rapports/thèses) : 2x un article
A45: FICHES MODÈLES (distinctes des fiches articles)
...

Sheet Estimation
A1: BRIDGES-Avatar — Scoping Review : estimation de charge par phase
A2: Toutes les estimations supposent UNE SEULE personne à temps plein. Volumes mesurés (Lens.org) et débit réel observé.
A4: Tâche | B4: Statut | C4: Volume | D4: Temps (h) | E4: Semaines | F4: Note
A5: PHASE 02 — Screening
A6: Screening titre/abstract restants | B6: À faire | C6: =Hypothèses!$B$18 -> 2011 | E6: =Hypothèses!$B$18/Hypothèses!$B$7 -> 5.7457143 | F6: Non-vus ASReview
A7: Téléchargement PDF — OA restants | B7: À faire | C7: =Hypothèses!$B$21 -> 329 | D7: =Hypothèses!$B$21*Hypothèses!$B$8/60 -> 16.45 | E7: =D7/Hypothèses!$B$12 -> 0.44459459 | F7: Manuel : recherche + DL + renommage
A8: Téléchargement PDF — demande biblio | B8: À faire | C8: =Hypothèses!$B$22 -> 277 | D8: =Hypothèses!$B$29*Hypothèses!$B$12/Hypothèses!$B$13 -> 3.7 | E8: =Hypothèses!$B$29/Hypothèses!$B$13 -> 0.1 | F8: Forfait ; hors délai biblio (externe)
A9: Snowballing — forward | B9: À faire | C9: =Hypothèses!$B$25 -> 9642 | E9: =Hypothèses!$B$25/Hypothèses!$B$7 -> 27.548571 | F9: Mesuré citationchaser (816 art.)
A10: Snowballing — backward | B10: À faire | C10: =Hypothèses!$B$26 -> 46644 | E10: =Hypothèses!$B$26/Hypothèses!$B$7 -> 133.26857 | F10: Mesuré citationchaser (816 art.)
A11: Snowballing — total brut | B11: — | C11: =C9+C10 -> 56286 | E11: =C11/Hypothèses!$B$7 -> 160.81714 | F11: Forward + backward
A12: Snowballing — net estimé (TRÈS approx.) | B12: À faire | C12: =C11*Hypothèses!$B$27 -> 22514.4 | E12: =C12/Hypothèses!$B$7 -> 64.326857 | F12: Voir note (*)
A13: Littérature grise — tri (FAO, thèses) | B13: À faire | C13: =Hypothèses!$B$40 -> 50 | D13: =C13*Hypothèses!$B$41/60 -> 20.833333 | E13: =D13/Hypothèses!$B$12 -> 0.56306306 | F13: Documents longs ; demandé par l'équipe
A15: PHASE 03 — Extraction des données
A16: Corpus 1 — inclus déjà identifiés (816)
A17: Extraction Python — déjà faite | B17: Fait | C17: =Hypothèses!$B$23 -> 207 | D17: =Hypothèses!$B$30*Hypothèses!$B$12/Hypothèses!$B$13 -> 3.7 | E17: =Hypothèses!$B$30/Hypothèses!$B$13 -> 0.1 | F17: ~½ j pour 207 art.
A18: Extraction Python — reste des inclus | B18: À faire | C18: =(Hypothèses!$B$19-Hypothèses!$B$23) -> 609 | D18: =C18/Hypothèses!$B$23*Hypothèses!$B$30*Hypothèses!$B$12/Hypothèses!$B$13 -> 10.885507 | E18: =C18/Hypothèses!$B$23*Hypothèses!$B$30/Hypothèses!$B$13 -> 0.2942029 | F18: Proportionnel, faible
A19: Full-text — tri (décision) | B19: À faire | C19: =Hypothèses!$B$19 -> 816 | D19: =C19*Hypothèses!$B$9/60 -> 204 | E19: =D19/Hypothèses!$B$12 -> 5.5135135 | F19: Sur les inclus
A20: Validation fiches articles | B20: En partie | C20: =Hypothèses!$B$19 -> 816 | D20: =C20*Hypothèses!$B$10/60 -> 272 | E20: =D20/Hypothèses!$B$12 -> 7.3513514 | F20: Relecture+correction (lent)
A21: Corpus 2 — nouveaux inclus (issus des 2011 × taux)
A22: Téléchargement PDF (manuel) | B22: À faire | C22: =Hypothèses!$B$18*Hypothèses!$B$37 -> 1005.5 | D22: =C22*Hypothèses!$B$8/60 -> 50.275 | E22: =D22/Hypothèses!$B$12 -> 1.3587838 | F22: Manuel ; OA + biblio confondus
A23: Extraction Python | B23: À faire | C23: =Hypothèses!$B$18*Hypothèses!$B$37 -> 1005.5 | D23: =C23/Hypothèses!$B$23*Hypothèses!$B$30*Hypothèses!$B$12/Hypothèses!$B$13 -> 17.972705 | E23: =C23/Hypothèses!$B$23*Hypothèses!$B$30/Hypothèses!$B$13 -> 0.48574879 | F23: Proportionnel
A24: Full-text — tri (décision) | B24: À faire | C24: =Hypothèses!$B$18*Hypothèses!$B$37 -> 1005.5 | D24: =C24*Hypothèses!$B$9/60 -> 251.375 | E24: =D24/Hypothèses!$B$12 -> 6.7939189 | F24: Sur les nouveaux inclus
A25: Validation fiches articles | B25: À faire | C25: =Hypothèses!$B$18*Hypothèses!$B$37 -> 1005.5 | D25: =C25*Hypothèses!$B$10/60 -> 335.16667 | E25: =D25/Hypothèses!$B$12 -> 9.0585586 | F25: Relecture+correction
A26: Corpus 3 — littérature grise retenue (FAO, thèses)
A27: Extraction Python | B27: À faire | C27: =Hypothèses!$B$40*Hypothèses!$B$42 -> 15 | D27: =C27/Hypothèses!$B$23*Hypothèses!$B$30*Hypothèses!$B$12/Hypothèses!$B$13 -> 0.26811594 | E27: =C27/Hypothèses!$B$23*Hypothèses!$B$30/Hypothèses!$B$13 -> 0.0072463768 | F27: Documents longs
A28: Validation fiches articles | B28: À faire | C28: =Hypothèses!$B$40*Hypothèses!$B$42 -> 15 | D28: =C28*Hypothèses!$B$43/60 -> 11.25 | E28: =D28/Hypothèses!$B$12 -> 0.30405405 | F28: 45 min/doc (long)
A29: Fiches modèles (transversales, distinctes des fiches articles)
A30: Validation fiches modèles | B30: En partie | C30: =Hypothèses!$B$46 -> 40 | D30: =C30*Hypothèses!$B$47/60 -> 40 | E30: =D30/Hypothèses!$B$12 -> 1.0810811 | F30: 1 par modèle canonique ; IA + vérif. experte
A31: Harmonisation + consolidation | B31: En partie | E31: =Hypothèses!$B$31 -> 0.5 | F31: Code + arbitrage modèles (après validations)
A33: PHASE 04 — Analyses & visualisation
A34: Radars / heatmap / clusters | B34: Fait | E34: 0 | F34: Produits (rapport Quarto)
A35: Finalisation analyses restantes | B35: À faire | E35: =Hypothèses!$B$32 -> 1 | F35: Mise en forme, take-home
A36: Faisabilité par site BRIDGES | B36: Bloqué | F36: Attend données site (équipe)
A37: Score composite de pertinence | B37: Bloqué | F37: Attend formule (équipe)
A38: Ateliers de co-construction | B38: Bloqué | F38: Activité (non chiffrable ici)
A40: PHASE 05 — Rédaction
A41: Manuscrit + suppléments + révisions | B41: À faire | E41: =Hypothèses!$B$33 -> 6 | F41: Forfait estimé
A42: Guide de choix de modèle (livrable) | B42: À faire | E42: =Hypothèses!$B$34 -> 1 | F42: Forfait estimé
A44: SYNTHÈSE — charge cumulative selon le périmètre (semaines-personne)
A45: A. Corpus 1 seul (816) + fiches modèles + analyses + rédaction | E45: =E7+E8+E18+E19+E20+E30+E31+E35+E41+E42 -> 23.284743 | F45: Finir le corpus déjà identifié
...
